Workbook
Name Slicer_Representative: #N/A

Sheet Dashboard
A1: CALL CENTER REPORT - 2023
Q19: {=pivot!C72:G72} -> R01 | R19: R02 | S19: R03 | T19: R04 | U19: R05 | V19: Total
P20: {=IF(pivot!B73:H90 = "","",pivot!B73:H90)} -> Cincinnati
P21: C0003 | Q21: 891 | R21: 1332 | S21: 1282 | T21: 739 | U21: 560 | V21: 4804
P22: C0004 | Q22: 1991 | R22: 1886 | S22: 1206 | T22: 884 | U22: 1722 | V22: 7689
P23: C0011 | Q23: 1163 | R23: 1180 | S23: 1616 | T23: 1043 | U23: 1747 | V23: 6749
P24: C0012 | Q24: 1438 | R24: 1616 | S24: 866 | T24: 829 | U24: 2070 | V24: 6819
P25: Cleveland
P26: C0002 | Q26: 1233 | R26: 223 | S26: 1680 | T26: 990 | U26: 1508 | V26: 5634
P27: C0007 | Q27: 1598 | R27: 1907 | S27: 869 | T27: 1426 | U27: 1416 | V27: 7216
L28: =pivot!J59 -> #VALUE! | P28: C0008 | Q28: 900 | R28: 1016 | S28: 960 | T28: 940 | U28: 1193 | V28: 5009
P29: C0010 | Q29: 900 | R29: 1470 | S29: 1617 | T29: 1314 | U29: 941 | V29: 6242
P30: C0013 | Q30: 1255 | R30: 516 | S30: 1874 | T30: 1863 | U30: 1722 | V30: 7230
P31: C0015 | Q31: 1138 | R31: 1898 | S31: 1482 | T31: 846 | U31: 1154 | V31: 6518
P32: Columbus
M33: =pivot!J55 -> % of calls:19% | P33: C0001 | Q33: 1655 | R33: 805 | S33: 2263 | T33: 987 | U33: 1075 | V33: 6785
M34: =pivot!J56 -> call rank:4 | P34: C0005 | Q34: 1104 | R34: 2280 | S34: 1445 | T34: 1722 | U34: 1196 | V34: 7747
M35: =pivot!J57 -> Amount rank:4 | P35: C0006 | Q35: 372 | R35: 1818 | S35: 1346 | T35: 1156 | U35: 1484 | V35: 6176
P36: C0009 | Q36: 1415 | R36: 1271 | S36: 1214 | T36: 1135 | U36: 1566 | V36: 6601
P37: C0014 | Q37: 1362 | R37: 1363 | S37: 1152 | T37: 777 | U37: 750 | V37: 5404

Sheet pivot
A3: Call Count | B3: Total Amount | C3: Total Duration | D3: Avg.rating | E3: 5*calls
A4: 1000 | B4: 96623 | C4: 89850 | D4: 3.8854 | E4: 307
A11: Call Count | B11: Total Amount | C11: Total Duration | D11: Avg.rating | E11: 5*calls
A12: 189 | B12: 18415 | C12: 16834 | D12: 3.9227513 | E12: 60
A19: Row Labels | B19: Call Count | C19: Call Count2
A20: Jan | B20: 16 | C20: 16 | I20: Row Labels | J20: Call Count
A21: Feb | B21: 14 | C21: 14 | I21: Sunday | J21: 36
A22: Mar | B22: 26 | C22: 26 | I22: Monday | J22: 30
A23: Apr | B23: 29 | C23: 29 | I23: Tuesday | J23: 13
A24: May | B24: 17 | C24: 17 | I24: Wednesday | J24: 23
A25: Jun | B25: 15 | C25: 15 | I25: Thursday | J25: 23
A26: Jul | B26: 15 | C26: 15 | I26: Friday | J26: 24
A27: Aug | B27: 7 | C27: 7 | I27: Saturday | J27: 40
A28: Sep | B28: 11 | C28: 11 | I28: Grand Total | J28: 189
A29: Oct | B29: 24 | C29: 24
A30: Nov | B30: 9 | C30: 9
A31: Dec | B31: 6 | C31: 6
A32: Grand Total | B32: 189 | C32: 189
G36: for graph | J36: selected rep | K36: =B49 -> R01
A37: Row Labels | B37: Count of Call number | C37: Total Amount | G37: Rep | H37: Calls | I37: Amount | J37: Sel.Calls | K37: Sel.Amount
A38: R01 | B38: 189 | C38: 18415 | G38: {=A38:C42} -> R01 | H38: 189 | I38: 18415 | J38: =IF(G38=$K$36,H38,NA()) -> 189 | K38: =IF(G38=$K$36,I38,NA()) -> 18415
A39: R02 | B39: 218 | C39: 20581 | G39: R02 | H39: 218 | I39: 20581 | J39: =IF(G39=$K$36,H39,NA()) -> #N/A | K39: =IF(G39=$K$36,I39,NA()) -> #N/A
A40: R03 | B40: 207 | C40: 20872 | G40: R03 | H40: 207 | I40: 20872 | J40: =IF(G40=$K$36,H40,NA()) -> #N/A | K40: =IF(G40=$K$36,I40,NA()) -> #N/A
A41: R04 | B41: 186 | C41: 16651 | G41: R04 | H41: 186 | I41: 16651 | J41: =IF(G41=$K$36,H41,NA()) -> #N/A | K41: =IF(G41=$K$36,I41,NA()) -> #N/A
A42: R05 | B42: 200 | C42: 20104 | G42: R05 | H42: 200 | I42: 20104 | J42: =IF(G42=$K$36,H42,NA()) -> #N/A | K42: =IF(G42=$K$36,I42,NA()) -> #N/A
A43: Grand Total | B43: 1000 | C43: 96623
I45: REP summary
I47: % of calls | J47: =A12/A4 -> 0.189
B48: Row Labels | I48: Calls | J48: =_xlfn.XLOOKUP(B49,G38:G42,H38:H42) -> 189
B49: R01 | I49: Amount | J49: =_xlfn.XLOOKUP(B49,G38:G42,I38:I42) -> 18415
I51: Call rank | J51: =_xlfn.RANK.AVG(J48,H38:H42) -> 4
I52: Amount rank | J52: =_xlfn.RANK.AVG(J49,I38:I42) -> 4
B54: Call Count | C54: Column Labels | I54: labels
B55: Row Labels | C55: Female | D55: Male | E55: Grand Total | J55: ="% of calls:"&(TEXT(J47,"0%")) -> % of calls:19%
B56: Cincinnati | C56: 144 | D56: 132 | E56: 276 | J56: =IF(COUNTA(B49:B53)>1,"","call rank:"&J51) -> call rank:4
B57: Cleveland | C57: 326 | D57: 63 | E57: 389 | J57: =IF(COUNTA(B49:B53)>1,"","Amount rank:"&J52) -> Amount rank:4
B58: Columbus | C58: 129 | D58: 206 | E58: 335
B59: Grand Total | C59: 599 | D59: 401 | E59: 1000 | I59: image: | J59: =IF(COUNTA(B49:B53)>1,"",_xlfn.XLOOKUP(B49,Assets!$E$3:$E$7,Assets!$F$3:$F$7)) -> #VALUE!
B63: Row Labels | C63: Call Count
B64: 1 | C64: 1
...

Sheet Data
B1: Call Centre Data
B3: Call number | C3: Customer ID | D3: Duration | E3: Representative | F3: Date of Call | G3: Purchase Amount | H3: Satisfaction Rating | I3: FY | J3: Day of week | K3: Duration Bucket | L3: Rating rounded | Q3: Customer ID | R3: Gedner | S3: Age | T3: City
B4: Call_7271 | C4: C0003 | D4: 116 | E4: R05 | F4: 44927 | G4: 128 | H4: 4.9 | I4: =IF(MONTH(calls[[#This Row],[Date of Call]])<=6, YEAR(calls[[#This Row],[Date of Call]]), YEAR(calls[[#This Row],[Date of Call]])+1) -> 2023 | J4: =TEXT(calls[[#This Row],[Date of Call]],"DDDD") -> Sunday | K4: {=_xlfn.IFS(calls[[#This Row],[Duration]]<=10,"Under 10 mins", calls[[#This Row],[Duration]]<=30, "10 to 30 mins", calls[[#This Row],[Duration]]<=60, "30 to 60 mins", calls[[#This Row],[Duration]]<=120, "1 to 2 hours", TRUE, "More than 2 hours")} -> 1 to 2 hours | L4: =ROUND(calls[[#This Row],[Satisfaction Rating]],0) -> 5 | Q4: C0001 | R4: Male | S4: 41 | T4: Columbus
B5: Call_7272 | C5: C0004 | D5: 119 | E5: R05 | F5: 44927 | G5: 135 | H5: 2.9 | I5: =IF(MONTH(calls[[#This Row],[Date of Call]])<=6, YEAR(calls[[#This Row],[Date of Call]]), YEAR(calls[[#This Row],[Date of Call]])+1) -> 2023 | J5: =TEXT(calls[[#This Row],[Date of Call]],"DDDD") -> Sunday | K5: {=_xlfn.IFS(calls[[#This Row],[Duration]]<=10,"Under 10 mins", calls[[#This Row],[Duration]]<=30, "10 to 30 mins", calls[[#This Row],[Duration]]<=60, "30 to 60 mins", calls[[#This Row],[Duration]]<=120, "1 to 2 hours", TRUE, "More than 2 hours")} -> 1 to 2 hours | L5: =ROUND(calls[[#This Row],[Satisfaction Rating]],0) -> 3 | Q5: C0002 | R5: Male | S5: 31 | T5: Cleveland
B6: Call_7273 | C6: C0005 | D6: 68 | E6: R02 | F6: 44927 | G6: 66 | H6: 4.7 | I6: =IF(MONTH(calls[[#This Row],[Date of Call]])<=6, YEAR(calls[[#This Row],[Date of Call]]), YEAR(calls[[#This Row],[Date of Call]])+1) -> 2023 | J6: =TEXT(calls[[#This Row],[Date of Call]],"DDDD") -> Sunday | K6: {=_xlfn.IFS(calls[[#This Row],[Duration]]<=10,"Under 10 mins", calls[[#This Row],[Duration]]<=30, "10 to 30 mins", calls[[#This Row],[Duration]]<=60, "30 to 60 mins", calls[[#This Row],[Duration]]<=120, "1 to 2 hours", TRUE, "More than 2 hours")} -> 1 to 2 hours | L6: =ROUND(calls[[#This Row],[Satisfaction Rating]],0) -> 5 | Q6: C0003 | R6: Male | S6: 26 | T6: Cincinnati
B7: Call_7274 | C7: C0014 | D7: 119 | E7: R02 | F7: 44927 | G7: 22 | H7: 2.9 | I7: =IF(MONTH(calls[[#This Row],[Date of Call]])<=6, YEAR(calls[[#This Row],[Date of Call]]), YEAR(calls[[#This Row],[Date of Call]])+1) -> 2023 | J7: =TEXT(calls[[#This Row],[Date of Call]],"DDDD") -> Sunday | K7: {=_xlfn.IFS(calls[[#This Row],[Duration]]<=10,"Under 10 mins", calls[[#This Row],[Duration]]<=30, "10 to 30 mins", calls[[#This Row],[Duration]]<=60, "30 to 60 mins", calls[[#This Row],[Duration]]<=120, "1 to 2 hours", TRUE, "More than 2 hours")} -> 1 to 2 hours | L7: =ROUND(calls[[#This Row],[Satisfaction Rating]],0) -> 3 | Q7: C0004 | R7: Male | S7: 36 | T7: Cincinnati
B8: Call_7275 | C8: C0011 | D8: 128 | E8: R01 | F8: 44928 | G8: 31 | H8: 2.8 | I8: =IF(MONTH(calls[[#This Row],[Date of Call]])<=6, YEAR(calls[[#This Row],[Date of Call]]), YEAR(calls[[#This Row],[Date of Call]])+1) -> 2023 | J8: =TEXT(calls[[#This Row],[Date of Call]],"DDDD") -> Monday | K8: {=_xlfn.IFS(calls[[#This Row],[Duration]]<=10,"Under 10 mins", calls[[#This Row],[Duration]]<=30, "10 to 30 mins", calls[[#This Row],[Duration]]<=60, "30 to 60 mins", calls[[#This Row],[Duration]]<=120, "1 to 2 hours", TRUE, "More than 2 hours")} -> More than 2 hours | L8: =ROUND(calls[[#This Row],[Satisfaction Rating]],0) -> 3 | Q8: C0005 | R8: Male | S8: 37 | T8: Columbus
B9: Call_7276 | C9: C0011 | D9: 49 | E9: R02 | F9: 44929 | G9: 135 | H9: 4.8 | I9: =IF(MONTH(calls[[#This Row],[Date of Call]])<=6, YEAR(calls[[#This Row],[Date of Call]]), YEAR(calls[[#This Row],[Date of Call]])+1) -> 2023 | J9: =TEXT(calls[[#This Row],[Date of Call]],"DDDD") -> Tuesday | K9: {=_xlfn.IFS(calls[[#This Row],[Duration]]<=10,"Under 10 mins", calls[[#This Row],[Duration]]<=30, "10 to 30 mins", calls[[#This Row],[Duration]]<=60, "30 to 60 mins", calls[[#This Row],[Duration]]<=120, "1 to 2 hours", TRUE, "More than 2 hours")} -> 30 to 60 mins | L9: =ROUND(calls[[#This Row],[Satisfaction Rating]],0) -> 5 | Q9: C0006 | R9: Male | S9: 23 | T9: Columbus
B10: Call_7277 | C10: C0007 | D10: 84 | E10: R05 | F10: 44929 | G10: 60 | H10: 4.7 | I10: =IF(MONTH(calls[[#This Row],[Date of Call]])<=6, YEAR(calls[[#This Row],[Date of Call]]), YEAR(calls[[#This Row],[Date of Call]])+1) -> 2023 | J10: =TEXT(calls[[#This Row],[Date of Call]],"DDDD") -> Tuesday | K10: {=_xlfn.IFS(calls[[#This Row],[Duration]]<=10,"Under 10 mins", calls[[#This Row],[Duration]]<=30, "10 to 30 mins", calls[[#This Row],[Duration]]<=60, "30 to 60 mins", calls[[#This Row],[Duration]]<=120, "1 to 2 hours", TRUE, "More than 2 hours")} -> 1 to 2 hours | L10: =ROUND(calls[[#This Row],[Satisfaction Rating]],0) -> 5 | Q10: C0007 | R10: Female | S10: 22 | T10: Cleveland
B11: Call_7278 | C11: C0003 | D11: 103 | E11: R04 | F11: 44929 | G11: 148 | H11: 4.4 | I11: =IF(MONTH(calls[[#This Row],[Date of Call]])<=6, YEAR(calls[[#This Row],[Date of Call]]), YEAR(calls[[#This Row],[Date of Call]])+1) -> 2023 | J11: =TEXT(calls[[#This Row],[Date of Call]],"DDDD") -> Tuesday | K11: {=_xlfn.IFS(calls[[#This Row],[Duration]]<=10,"Under 10 mins", calls[[#This Row],[Duration]]<=30, "10 to 30 mins", calls[[#This Row],[Duration]]<=60, "30 to 60 mins", calls[[#This Row],[Duration]]<=120, "1 to 2 hours", TRUE, "More than 2 hours")} -> 1 to 2 hours | L11: =ROUND(calls[[#This Row],[Satisfaction Rating]],0) -> 4 | Q11: C0008 | R11: Female | S11: 42 | T11: Cleveland
B12: Call_7279 | C12: C0005 | D12: 31 | E12: R02 | F12: 44929 | G12: 135 | H12: 3.6 | I12: =IF(MONTH(calls[[#This Row],[Date of Call]])<=6, YEAR(calls[[#This Row],[Date of Call]]), YEAR(calls[[#This Row],[Date of Call]])+1) -> 2023 | J12: =TEXT(calls[[#This Row],[Date of Call]],"DDDD") -> Tuesday | K12: {=_xlfn.IFS(calls[[#This Row],[Duration]]<=10,"Under 10 mins", calls[[#This Row],[Duration]]<=30, "10 to 30 mins", calls[[#This Row],[Duration]]<=60, "30 to 60 mins", calls[[#This Row],[Duration]]<=120, "1 to 2 hours", TRUE, "More than 2 hours")} -> 30 to 60 mins | L12: =ROUND(calls[[#This Row],[Satisfaction Rating]],0) -> 4 | Q12: C0009 | R12: Female | S12: 25 | T12: Columbus
B13: Call_7280 | C13: C0010 | D13: 44 | E13: R03 | F13: 44929 | G13: 105 | H13: 2.9 | I13: =IF(MONTH(calls[[#This Row],[Date of Call]])<=6, YEAR(calls[[#This Row],[Date of Call]]), YEAR(calls[[#This Row],[Date of Call]])+1) -> 2023 | J13: =TEXT(calls[[#This Row],[Date of Call]],"DDDD") -> Tuesday | K13: {=_xlfn.IFS(calls[[#This Row],[Duration]]<=10,"Under 10 mins", calls[[#This Row],[Duration]]<=30, "10 to 30 mins", calls[[#This Row],[Duration]]<=60, "30 to 60 mins", calls[[#This Row],[Duration]]<=120, "1 to 2 hours", TRUE, "More than 2 hours")} -> 30 to 60 mins | L13: =ROUND(calls[[#This Row],[Satisfaction Rating]],0) -> 3 | Q13: C0010 | R13: Female | S13: 30 | T13: Cleveland
B14: Call_7281 | C14: C0011 | D14: 102 | E14: R02 | F14: 44929 | G14: 69 | H14: 4.9 | I14: =IF(MONTH(calls[[#This Row],[Date of Call]])<=6, YEAR(calls[[#This Row],[Date of Call]]), YEAR(calls[[#This Row],[Date of Call]])+1) -> 2023 | J14: =TEXT(calls[[#This Row],[Date of Call]],"DDDD") -> Tuesday | K14: {=_xlfn.IFS(calls[[#This Row],[Duration]]<=10,"Under 10 mins", calls[[#This Row],[Duration]]<=30, "10 to 30 mins", calls[[#This Row],[Duration]]<=60, "30 to 60 mins", calls[[#This Row],[Duration]]<=120, "1 to 2 hours", TRUE, "More than 2 hours")} -> 1 to 2 hours | L14: =ROUND(calls[[#This Row],[Satisfaction Rating]],0) -> 5 | Q14: C0011 | R14: Female | S14: 30 | T14: Cincinnati
B15: Call_7282 | C15: C0013 | D15: 135 | E15: R05 | F15: 44929 | G15: 46 | H15: 3.4 | I15: =IF(MONTH(calls[[#This Row],[Date of Call]])<=6, YEAR(calls[[#This Row],[Date of Call]]), YEAR(calls[[#This Row],[Date of Call]])+1) -> 2023 | J15: =TEXT(calls[[#This Row],[Date of Call]],"DDDD") -> Tuesday | K15: {=_xlfn.IFS(calls[[#This Row],[Duration]]<=10,"Under 10 mins", calls[[#This Row],[Duration]]<=30, "10 to 30 mins", calls[[#This Row],[Duration]]<=60, "30 to 60 mins", calls[[#This Row],[Duration]]<=120, "1 to 2 hours", TRUE, "More than 2 hours")} -> More than 2 hours | L15: =ROUND(calls[[#This Row],[Satisfaction Rating]],0) -> 3 | Q15: C0012 | R15: Female | S15: 28 | T15: Cincinnati
... B18: Call_7285 | C18: C0013 | D18: 48 | E18: R01 | F18: 44930 | G18: 68 | H18: 4.9 | I18: =IF(MONTH(calls[[#This Row],[Date of Call]])<=6, YEAR(calls[[#This Row],[Date of Call]]), YEAR(calls[[#This Row],[Date of Call]])+1) -> 2023 | J18: =TEXT(calls[[#This Row],[Date of Call]],"DDDD") -> Wednesday | K18: {=_xlfn.IFS(calls[[#This Row],[Duration]]<=10,"Under 10 mins", calls[[#This Row],[Duration]]<=30, "10 to 30 mins", calls[[#This Row],[Duration]]<=60, "30 to 60 mins", calls[[#This Row],[Duration]]<=120, "1 to 2 hours", TRUE, "More than 2 hours")} -> 30 to 60 mins | L18: =ROUND(calls[[#This Row],[Satisfaction Rating]],0) -> 5 | Q18: C0015 | R18: Female | S18: 43 | T18: Cleveland
B19: Call_7286 | C19: C0010 | D19: 176 | E19: R05 | F19: 44931 | G19: 24 | H19: 4.8 | I19: =IF(MONTH(calls[[#This Row],[Date of Call]])<=6, YEAR(calls[[#This Row],[Date of Call]]), YEAR(calls[[#This Row],[Date of Call]])+1) -> 2023 | J19: =TEXT(calls[[#This Row],[Date of Call]],"DDDD") -> Thursday | K19: {=_xlfn.IFS(calls[[#This Row],[Duration]]<=10,"Under 10 mins", calls[[#This Row],[Duration]]<=30, "10 to 30 mins", calls[[#This Row],[Duration]]<=60, "30 to 60 mins", calls[[#This Row],[Duration]]<=120, "1 to 2 hours", TRUE, "More than 2 hours")} -> More than 2 hours | L19: =ROUND(calls[[#This Row],[Satisfaction Rating]],0) -> 5
B20: Call_7287 | C20: C0010 | D20: 99 | E20: R01 | F20: 44931 | G20: 195 | H20: 3.9 | I20: =IF(MONTH(calls[[#This Row],[Date of Call]])<=6, YEAR(calls[[#This Row],[Date of Call]]), YEAR(calls[[#This Row],[Date of Call]])+1) -> 2023 | J20: =TEXT(calls[[#This Row],[Date of Call]],"DDDD") -> Thursday | K20: {=_xlfn.IFS(calls[[#This Row],[Duration]]<=10,"Under 10 mins", calls[[#This Row],[Duration]]<=30, "10 to 30 mins", calls[[#This Row],[Duration]]<=60, "30 to 60 mins", calls[[#This Row],[Duration]]<=120, "1 to 2 hours", TRUE, "More than 2 hours")} -> 1 to 2 hours | L20: =ROUND(calls[[#This Row],[Satisfaction Rating]],0) -> 4
B21: Call_7288 | C21: C0009 | D21: 28 | E21: R03 | F21: 44931 | G21: 28 | H21: 3.8 | I21: =IF(MONTH(calls[[#This Row],[Date of Call]])<=6, YEAR(calls[[#This Row],[Date of Call]]), YEAR(calls[[#This Row],[Date of Call]])+1) -> 2023 | J21: =TEXT(calls[[#This Row],[Date of Call]],"DDDD") -> Thursday | K21: {=_xlfn.IFS(calls[[#This Row],[Duration]]<=10,"Under 10 mins", calls[[#This Row],[Duration]]<=30, "10 to 30 mins", calls[[#This Row],[Duration]]<=60, "30 to 60 mins", calls[[#This Row],[Duration]]<=120, "1 to 2 hours", TRUE, "More than 2 hours")} -> 10 to 30 mins | L21: =ROUND(calls[[#This Row],[Satisfaction Rating]],0) -> 4
B22: Call_7289 | C22: C0007 | D22: 54 | E22: R02 | F22: 44931 | G22: 170 | H22: 4.3 | I22: =IF(MONTH(calls[[#This Row],[Date of Call]])<=6, YEAR(calls[[#This Row],[Date of Call]]), YEAR(calls[[#This Row],[Date of Call]])+1) -> 2023 | J22: =TEXT(calls[[#This Row],[Date of Call]],"DDDD") -> Thursday | K22: {=_xlfn.IFS(calls[[#This Row],[Duration]]<=10,"Under 10 mins", calls[[#This Row],[Duration]]<=30, "10 to 30 mins", calls[[#This Row],[Duration]]<=60, "30 to 60 mins", calls[[#This Row],[Duration]]<=120, "1 to 2 hours", TRUE, "More than 2 hours")} -> 30 to 60 mins | L22: =ROUND(calls[[#This Row],[Satisfaction Rating]],0) -> 4
B23: Call_7290 | C23: C0006 | D23: 48 | E23: R05 | F23: 44932 | G23: 30 | H23: 4.4 | I23: =IF(MONTH(calls[[#This Row],[Date of Call]])<=6, YEAR(calls[[#This Row],[Date of Call]]), YEAR(calls[[#This Row],[Date of Call]])+1) -> 2023 | J23: =TEXT(calls[[#This Row],[Date of Call]],"DDDD") -> Friday | K23: {=_xlfn.IFS(calls[[#This Row],[Duration]]<=10,"Under 10 mins", calls[[#This Row],[Duration]]<=30, "10 to 30 mins", calls[[#This Row],[Duration]]<=60, "30 to 60 mins", calls[[#This Row],[Duration]]<=120, "1 to 2 hours", TRUE, "More than 2 hours")} -> 30 to 60 mins | L23: =ROUND(calls[[#This Row],[Satisfaction Rating]],0) -> 4
B24: Call_7291 | C24: C0004 | D24: 128 | E24: R05 | F24: 44932 | G24: 72 | H24: 5 | I24: =IF(MONTH(calls[[#This Row],[Date of Call]])<=6, YEAR(calls[[#This Row],[Date of Call]]), YEAR(calls[[#This Row],[Date of Call]])+1) -> 2023 | J24: =TEXT(calls[[#This Row],[Date of Call]],"DDDD") -> Friday | K24: {=_xlfn.IFS(calls[[#This Row],[Duration]]<=10,"Under 10 mins", calls[[#This Row],[Duration]]<=30, "10 to 30 mins", calls[[#This Row],[Duration]]<=60, "30 to 60 mins", calls[[#This Row],[Duration]]<=120, "1 to 2 hours", TRUE, "More than 2 hours")} -> More than 2 hours | L24: =ROUND(calls[[#This Row],[Satisfaction Rating]],0) -> 5
B25: Call_7292 | C25: C0004 | D25: 38 | E25: R04 | F25: 44933 | G25: 92 | H25: 4.9 | I25: =IF(MONTH(calls[[#This Row],[Date of Call]])<=6, YEAR(calls[[#This Row],[Date of Call]]), YEAR(calls[[#This Row],[Date of Call]])+1) -> 2023 | J25: =TEXT(calls[[#This Row],[Date of Call]],"DDDD") -> Saturday | K25: {=_xlfn.IFS(calls[[#This Row],[Duration]]<=10,"Under 10 mins", calls[[#This Row],[Duration]]<=30, "10 to 30 mins", calls[[#This Row],[Duration]]<=60, "30 to 60 mins", calls[[#This Row],[Duration]]<=120, "1 to 2 hours", TRUE, "More than 2 hours")} -> 30 to 60 mins | L25: =ROUND(calls[[#This Row],[Satisfaction Rating]],0) -> 5
B26: Call_7293 | C26: C0003 | D26: 67 | E26: R04 | F26: 44934 | G26: 165 | H26: 4.5 | I26: =IF(MONTH(calls[[#This Row],[Date of Call]])<=6, YEAR(calls[[#This Row],[Date of Call]]), YEAR(calls[[#This Row],[Date of Call]])+1) -> 2023 | J26: =TEXT(calls[[#This Row],[Date of Call]],"DDDD") -> Sunday | K26: {=_xlfn.IFS(calls[[#This Row],[Duration]]<=10,"Under 10 mins", calls[[#This Row],[Duration]]<=30, "10 to 30 mins", calls[[#This Row],[Duration]]<=60, "30 to 60 mins", calls[[#This Row],[Duration]]<=120, "1 to 2 hours", TRUE, "More than 2 hours")} -> 1 to 2 hours | L26: =ROUND(calls[[#This Row],[Satisfaction Rating]],0) -> 5
B27: Call_7294 | C27: C0015 | D27: 58 | E27: R02 | F27: 44934 | G27: 140 | H27: 2.1 | I27: =IF(MONTH(calls[[#This Row],[Date of Call]])<=6, YEAR(calls[[#This Row],[Date of Call]]), YEAR(calls[[#This Row],[Date of Call]])+1) -> 2023 | J27: =TEXT(calls[[#This Row],[Date of Call]],"DDDD") -> Sunday | K27: {=_xlfn.IFS(calls[[#This Row],[Duration]]<=10,"Under 10 mins", calls[[#This Row],[Duration]]<=30, "10 to 30 mins", calls[[#This Row],[Duration]]<=60, "30 to 60 mins", calls[[#This Row],[Duration]]<=120, "1 to 2 hours", TRUE, "More than 2 hours")} -> 30 to 60 mins | L27: =ROUND(calls[[#This Row],[Satisfaction Rating]],0) -> 2
B28: Call_7295 | C28: C0010 | D28: 54 | E28: R01 | F28: 44934 | G28: 111 | H28: 3.3 | I28: =IF(MONTH(calls[[#This Row],[Date of Call]])<=6, YEAR(calls[[#This Row],[Date of Call]]), YEAR(calls[[#This Row],[Date of Call]])+1) -> 2023 | J28: =TEXT(calls[[#This Row],[Date of Call]],"DDDD") -> Sunday | K28: {=_xlfn.IFS(calls[[#This Row],[Duration]]<=10,"Under 10 mins", calls[[#This Row],[Duration]]<=30, "10 to 30 mins", calls[[#This Row],[Duration]]<=60, "30 to 60 mins", calls[[#This Row],[Duration]]<=120, "1 to 2 hours", TRUE, "More than 2 hours")} -> 30 to 60 mins | L28: =ROUND(calls[[#This Row],[Satisfaction Rating]],0) -> 3
B29: Call_7296 | C29: C0012 | D29: 28 | E29: R05 | F29: 44935 | G29: 63 | H29: 4.1 | I29: =IF(MONTH(calls[[#This Row],[Date of Call]])<=6, YEAR(calls[[#This Row],[Date of Call]]), YEAR(calls[[#This Row],[Date of Call]])+1) -> 2023 | J29: =TEXT(calls[[#This Row],[Date of Call]],"DDDD") -> Monday | K29: {=_xlfn.IFS(calls[[#This Row],[Duration]]<=10,"Under 10 mins", calls[[#This Row],[Duration]]<=30, "10 to 30 mins", calls[[#This Row],[Duration]]<=60, "30 to 60 mins", calls[[#This Row],[Duration]]<=120, "1 to 2 hours", TRUE, "More than 2 hours")} -> 10 to 30 mins | L29: =ROUND(calls[[#This Row],[Satisfaction Rating]],0) -> 4
B30: Call_7297 | C30: C0002 | D30: 73 | E30: R05 | F30: 44935 | G30: 80 | H30: 4.2 | I30: =IF(MONTH(calls[[#This Row],[Date of Call]])<=6, YEAR(calls[[#This Row],[Date of Call]]), YEAR(calls[[#This Row],[Date of Call]])+1) -> 2023 | J30: =TEXT(calls[[#This Row],[Date of Call]],"DDDD") -> Monday | K30: {=_xlfn.IFS(calls[[#This Row],[Duration]]<=10,"Under 10 mins", calls[[#This Row],[Duration]]<=30, "10 to 30 mins", calls[[#This Row],[Duration]]<=60, "30 to 60 mins", calls[[#This Row],[Duration]]<=120, "1 to 2 hours", TRUE, "More than 2 hours")} -> 1 to 2 hours | L30: =ROUND(calls[[#This Row],[Satisfaction Rating]],0) -> 4
... B1003: Call_8270 | C1003: C0009 | D1003: 114 | E1003: R01 | F1003: 45291 | G1003: 40 | H1003: 3.9 | I1003: =IF(MONTH(calls[[#This Row],[Date of Call]])<=6, YEAR(calls[[#This Row],[Date of Call]]), YEAR(calls[[#This Row],[Date of Call]])+1) -> 2024 | J1003: =TEXT(calls[[#This Row],[Date of Call]],"DDDD") -> Sunday | K1003: {=_xlfn.IFS(calls[[#This Row],[Duration]]<=10,"Under 10 mins", calls[[#This Row],[Duration]]<=30, "10 to 30 mins", calls[[#This Row],[Duration]]<=60, "30 to 60 mins", calls[[#This Row],[Duration]]<=120, "1 to 2 hours", TRUE, "More than 2 hours")} -> 1 to 2 hours | L1003: =ROUND(calls[[#This Row],[Satisfaction Rating]],0) -> 4

Sheet Assets
E2: Rep ID | F2: Rep Image
E3: R01 | F3: #VALUE!
E4: R02 | F4: #VALUE!
E5: R03 | F5: #VALUE!
E6: R04 | F6: #VALUE!
E7: R05 | F7: #VALUE!
